<!doctype html>
<html lang="en">

  <head>
  <meta charset="UTF-8">
  <meta name="viewport" content="width=device-width, initial-scale=1.0">

  <title>
    
      Nested exceptions in Ruby 2.1.0 &middot; Plough => Ruby
    
  </title>

  <link rel="stylesheet" href="/styles.css">
  <link rel="apple-touch-icon-precomposed" sizes="144x144" href="/assets/apple-touch-icon-precomposed.png">
  <link rel="shortcut icon" href="/assets/favicon.ico">
  <link rel="alternate" type="application/atom+xml" title="Plough => Ruby" href="/atom.xml">

  <!-- Begin Jekyll SEO tag v2.6.1 -->
<meta name="generator" content="Jekyll v4.0.0" />
<meta property="og:title" content="Nested exceptions in Ruby 2.1.0" />
<meta name="author" content="andhapp" />
<meta property="og:locale" content="en_US" />
<meta name="description" content="With Ruby 2.1.0, one can easily trace the original exception. Previously, on rescuing an exception one would have no reference to the original exception (thrown by a gem/library). There are a couple of gems that can help you keep track of the exceptions, but with Ruby 2.1.0 you can work with nested exceptions without any issues. Here’s some trivial code to achieve the same:" />
<meta property="og:description" content="With Ruby 2.1.0, one can easily trace the original exception. Previously, on rescuing an exception one would have no reference to the original exception (thrown by a gem/library). There are a couple of gems that can help you keep track of the exceptions, but with Ruby 2.1.0 you can work with nested exceptions without any issues. Here’s some trivial code to achieve the same:" />
<link rel="canonical" href="http://localhost:4000/2014/01/06/nested-exception-in-ruby-2.1.0/" />
<meta property="og:url" content="http://localhost:4000/2014/01/06/nested-exception-in-ruby-2.1.0/" />
<meta property="og:site_name" content="Plough =&gt; Ruby" />
<meta property="og:type" content="article" />
<meta property="article:published_time" content="2014-01-06T00:00:00+00:00" />
<script type="application/ld+json">
{"url":"http://localhost:4000/2014/01/06/nested-exception-in-ruby-2.1.0/","@type":"BlogPosting","headline":"Nested exceptions in Ruby 2.1.0","dateModified":"2014-01-06T00:00:00+00:00","datePublished":"2014-01-06T00:00:00+00:00","mainEntityOfPage":{"@type":"WebPage","@id":"http://localhost:4000/2014/01/06/nested-exception-in-ruby-2.1.0/"},"author":{"@type":"Person","name":"andhapp"},"description":"With Ruby 2.1.0, one can easily trace the original exception. Previously, on rescuing an exception one would have no reference to the original exception (thrown by a gem/library). There are a couple of gems that can help you keep track of the exceptions, but with Ruby 2.1.0 you can work with nested exceptions without any issues. Here’s some trivial code to achieve the same:","@context":"https://schema.org"}</script>
<!-- End Jekyll SEO tag -->

</head>


  <body>

    <div class="container content">
      <header class="masthead">
        <h3 class="masthead-title">
          <a href="/" title="Home">Plough => Ruby</a>
          <small>Journey through ruby</small>
        </h3>
      </header>

      <main>
        <article class="post">
  <h1 class="post-title">Nested exceptions in Ruby 2.1.0</h1>
  <time datetime="2014-01-06T00:00:00+00:00" class="post-date">06 Jan 2014</time>
  <p>With Ruby 2.1.0, one can easily trace the original exception.
Previously, on rescuing an exception one would have no reference to the original exception
(thrown by a gem/library). There are a couple of <a href="https://github.com/skorks/nesty">gems</a> that can help you
keep track of the exceptions, but with Ruby 2.1.0 you can work with
nested exceptions without any issues. Here’s some trivial code to
achieve the same:</p>

<div class="highlighter-rouge"><div class="highlight"><pre class="highlight"><code>class Car
  def self.start
    begin
      1/0
    rescue =&gt; ex
      puts "Exception: #{ex}"
      raise StandardError.new "Can't start the car"
    end
   end
end

begin
  Car.start
rescue =&gt; ex
  puts "Cause: #{ex.cause}"
  puts "Exception: #{ex}"
end
</code></pre></div></div>

<p>This will produce the following output:</p>
<div class="highlighter-rouge"><div class="highlight"><pre class="highlight"><code>Exception: divided by 0
Cause: divided by 0
Exception: Can't start the car
</code></pre></div></div>

<p>You can <a href="https://eval.in/86466">play around</a> with the code yourself.
It’s not as sophisticated as the gems out there, but it’s getting there.</p>

</article>


<aside class="related">
  <h3>Related posts</h3>
  <ul class="related-posts">
    
      <li>
        <a href="/2019/09/27/yarn-install-on-mojave/">
          Yarn Install On Mojave
          <small><time datetime="2019-09-27T00:00:00+01:00">27 Sep 2019</time></small>
        </a>
      </li>
    
      <li>
        <a href="/2019/09/27/installing-ffi-1.11.1-on-mojave/">
          Installing Ffi 1.11.1 On Mojave
          <small><time datetime="2019-09-27T00:00:00+01:00">27 Sep 2019</time></small>
        </a>
      </li>
    
      <li>
        <a href="/2016/10/06/dont-blindly-follow-blog-posts/">
          Dont Blindly Follow Blog Posts
          <small><time datetime="2016-10-06T00:00:00+01:00">06 Oct 2016</time></small>
        </a>
      </li>
    
  </ul>
</aside>


      </main>

      <footer class="footer">
        <small>
          &copy; <time datetime="2021-07-03T06:18:22+01:00">2021</time>. All rights reserved.
        </small>
      </footer>
    </div>

    
  </body>
</html>
